{
 "cells": [
  {
   "cell_type": "code",
   "execution_count": 1,
   "metadata": {},
   "outputs": [],
   "source": [
    "import json\n",
    "import bottle\n",
    "from bottle import route, run, request, abort\n",
    "from pymongo import MongoClient\n",
    "\n",
    "connection = MongoClient('localhost', 27017)\n",
    "db = connection.mydatabase"
   ]
  },
  {
   "cell_type": "code",
   "execution_count": 2,
   "metadata": {},
   "outputs": [],
   "source": [
    "@route('/documents', method='PUT')\n",
    "def put_document():\n",
    "    data = request.body.readline()\n",
    "    if not data:\n",
    "        abort(400, 'No data received')\n",
    "    entity = json.loads(data)\n",
    "    if not entity.has_key('_id'):\n",
    "        abort(400, 'No _id specified')\n",
    "    try:\n",
    "        db['documents'].save(entity)\n",
    "    except ValidationError as ve:\n",
    "        abort(400, str(ve))\n",
    "\n",
    "@route('/documents/:id', method=\"GET\")\n",
    "def get_document(id):\n",
    "    entity = db['documents'].find_one({'_id':id})\n",
    "    if not entity:\n",
    "        abort(404, 'No document with id %s' % id)\n",
    "    return entity"
   ]
  },
  {
   "cell_type": "code",
   "execution_count": null,
   "metadata": {},
   "outputs": [
    {
     "name": "stderr",
     "output_type": "stream",
     "text": [
      "Bottle v0.12.13 server starting up (using WSGIRefServer())...\n",
      "Listening on http://localhost:8080/\n",
      "Hit Ctrl-C to quit.\n",
      "\n",
      "Traceback (most recent call last):\n",
      "  File \"/anaconda3/lib/python3.7/site-packages/bottle.py\", line 862, in _handle\n",
      "    return route.call(**args)\n",
      "  File \"/anaconda3/lib/python3.7/site-packages/bottle.py\", line 1740, in wrapper\n",
      "    rv = callback(*a, **ka)\n",
      "  File \"<ipython-input-2-7fa93a6709a8>\", line 16, in get_document\n",
      "    entity = db['documents'].find_one({'_id':id})\n",
      "  File \"/anaconda3/lib/python3.7/site-packages/pymongo/collection.py\", line 1262, in find_one\n",
      "    for result in cursor.limit(-1):\n",
      "  File \"/anaconda3/lib/python3.7/site-packages/pymongo/cursor.py\", line 1189, in next\n",
      "    if len(self.__data) or self._refresh():\n",
      "  File \"/anaconda3/lib/python3.7/site-packages/pymongo/cursor.py\", line 1087, in _refresh\n",
      "    self.__session = self.__collection.database.client._ensure_session()\n",
      "  File \"/anaconda3/lib/python3.7/site-packages/pymongo/mongo_client.py\", line 1563, in _ensure_session\n",
      "    return self.__start_session(True, causal_consistency=False)\n",
      "  File \"/anaconda3/lib/python3.7/site-packages/pymongo/mongo_client.py\", line 1516, in __start_session\n",
      "    server_session = self._get_server_session()\n",
      "  File \"/anaconda3/lib/python3.7/site-packages/pymongo/mongo_client.py\", line 1549, in _get_server_session\n",
      "    return self._topology.get_server_session()\n",
      "  File \"/anaconda3/lib/python3.7/site-packages/pymongo/topology.py\", line 427, in get_server_session\n",
      "    None)\n",
      "  File \"/anaconda3/lib/python3.7/site-packages/pymongo/topology.py\", line 199, in _select_servers_loop\n",
      "    self._error_message(selector))\n",
      "pymongo.errors.ServerSelectionTimeoutError: localhost:27017: [Errno 61] Connection refused\n",
      "127.0.0.1 - - [26/Nov/2018 18:32:06] \"GET /documents/1 HTTP/1.1\" 500 752\n",
      "Traceback (most recent call last):\n",
      "  File \"/anaconda3/lib/python3.7/wsgiref/handlers.py\", line 138, in run\n",
      "    self.finish_response()\n",
      "  File \"/anaconda3/lib/python3.7/wsgiref/handlers.py\", line 180, in finish_response\n",
      "    self.write(data)\n",
      "  File \"/anaconda3/lib/python3.7/wsgiref/handlers.py\", line 274, in write\n",
      "    self.send_headers()\n",
      "  File \"/anaconda3/lib/python3.7/wsgiref/handlers.py\", line 332, in send_headers\n",
      "    self.send_preamble()\n",
      "  File \"/anaconda3/lib/python3.7/wsgiref/handlers.py\", line 255, in send_preamble\n",
      "    ('Date: %s\\r\\n' % format_date_time(time.time())).encode('iso-8859-1')\n",
      "  File \"/anaconda3/lib/python3.7/wsgiref/handlers.py\", line 453, in _write\n",
      "    result = self.stdout.write(data)\n",
      "  File \"/anaconda3/lib/python3.7/socketserver.py\", line 796, in write\n",
      "    self._sock.sendall(b)\n",
      "BrokenPipeError: [Errno 32] Broken pipe\n",
      "127.0.0.1 - - [26/Nov/2018 18:32:06] \"GET /documents/1 HTTP/1.1\" 500 59\n",
      "----------------------------------------\n",
      "Exception happened during processing of request from ('127.0.0.1', 58352)\n",
      "Traceback (most recent call last):\n",
      "  File \"/anaconda3/lib/python3.7/wsgiref/handlers.py\", line 138, in run\n",
      "    self.finish_response()\n",
      "  File \"/anaconda3/lib/python3.7/wsgiref/handlers.py\", line 180, in finish_response\n",
      "    self.write(data)\n",
      "  File \"/anaconda3/lib/python3.7/wsgiref/handlers.py\", line 274, in write\n",
      "    self.send_headers()\n",
      "  File \"/anaconda3/lib/python3.7/wsgiref/handlers.py\", line 332, in send_headers\n",
      "    self.send_preamble()\n",
      "  File \"/anaconda3/lib/python3.7/wsgiref/handlers.py\", line 255, in send_preamble\n",
      "    ('Date: %s\\r\\n' % format_date_time(time.time())).encode('iso-8859-1')\n",
      "  File \"/anaconda3/lib/python3.7/wsgiref/handlers.py\", line 453, in _write\n",
      "    result = self.stdout.write(data)\n",
      "  File \"/anaconda3/lib/python3.7/socketserver.py\", line 796, in write\n",
      "    self._sock.sendall(b)\n",
      "BrokenPipeError: [Errno 32] Broken pipe\n",
      "\n",
      "During handling of the above exception, another exception occurred:\n",
      "\n",
      "Traceback (most recent call last):\n",
      "  File \"/anaconda3/lib/python3.7/wsgiref/handlers.py\", line 141, in run\n",
      "    self.handle_error()\n",
      "  File \"/anaconda3/lib/python3.7/wsgiref/handlers.py\", line 368, in handle_error\n",
      "    self.finish_response()\n",
      "  File \"/anaconda3/lib/python3.7/wsgiref/handlers.py\", line 180, in finish_response\n",
      "    self.write(data)\n",
      "  File \"/anaconda3/lib/python3.7/wsgiref/handlers.py\", line 274, in write\n",
      "    self.send_headers()\n",
      "  File \"/anaconda3/lib/python3.7/wsgiref/handlers.py\", line 331, in send_headers\n",
      "    if not self.origin_server or self.client_is_modern():\n",
      "  File \"/anaconda3/lib/python3.7/wsgiref/handlers.py\", line 344, in client_is_modern\n",
      "    return self.environ['SERVER_PROTOCOL'].upper() != 'HTTP/0.9'\n",
      "TypeError: 'NoneType' object is not subscriptable\n",
      "\n",
      "During handling of the above exception, another exception occurred:\n",
      "\n",
      "Traceback (most recent call last):\n",
      "  File \"/anaconda3/lib/python3.7/socketserver.py\", line 313, in _handle_request_noblock\n",
      "    self.process_request(request, client_address)\n",
      "  File \"/anaconda3/lib/python3.7/socketserver.py\", line 344, in process_request\n",
      "    self.finish_request(request, client_address)\n",
      "  File \"/anaconda3/lib/python3.7/socketserver.py\", line 357, in finish_request\n",
      "    self.RequestHandlerClass(request, client_address, self)\n",
      "  File \"/anaconda3/lib/python3.7/socketserver.py\", line 717, in __init__\n",
      "    self.handle()\n",
      "  File \"/anaconda3/lib/python3.7/wsgiref/simple_server.py\", line 133, in handle\n",
      "    handler.run(self.server.get_app())\n",
      "  File \"/anaconda3/lib/python3.7/wsgiref/handlers.py\", line 144, in run\n",
      "    self.close()\n",
      "  File \"/anaconda3/lib/python3.7/wsgiref/simple_server.py\", line 35, in close\n",
      "    self.status.split(' ',1)[0], self.bytes_sent\n",
      "AttributeError: 'NoneType' object has no attribute 'split'\n",
      "----------------------------------------\n",
      "127.0.0.1 - - [26/Nov/2018 18:32:06] \"GET / HTTP/1.1\" 404 720\n",
      "Traceback (most recent call last):\n",
      "  File \"/anaconda3/lib/python3.7/wsgiref/handlers.py\", line 138, in run\n",
      "    self.finish_response()\n",
      "  File \"/anaconda3/lib/python3.7/wsgiref/handlers.py\", line 180, in finish_response\n",
      "    self.write(data)\n",
      "  File \"/anaconda3/lib/python3.7/wsgiref/handlers.py\", line 274, in write\n",
      "    self.send_headers()\n",
      "  File \"/anaconda3/lib/python3.7/wsgiref/handlers.py\", line 332, in send_headers\n",
      "    self.send_preamble()\n",
      "  File \"/anaconda3/lib/python3.7/wsgiref/handlers.py\", line 258, in send_preamble\n",
      "    self._write(('Server: %s\\r\\n' % self.server_software).encode('iso-8859-1'))\n",
      "  File \"/anaconda3/lib/python3.7/wsgiref/handlers.py\", line 453, in _write\n",
      "    result = self.stdout.write(data)\n",
      "  File \"/anaconda3/lib/python3.7/socketserver.py\", line 796, in write\n",
      "    self._sock.sendall(b)\n",
      "BrokenPipeError: [Errno 32] Broken pipe\n",
      "127.0.0.1 - - [26/Nov/2018 18:32:06] \"GET / HTTP/1.1\" 500 59\n",
      "----------------------------------------\n",
      "Exception happened during processing of request from ('127.0.0.1', 58354)\n",
      "Traceback (most recent call last):\n",
      "  File \"/anaconda3/lib/python3.7/wsgiref/handlers.py\", line 138, in run\n",
      "    self.finish_response()\n",
      "  File \"/anaconda3/lib/python3.7/wsgiref/handlers.py\", line 180, in finish_response\n",
      "    self.write(data)\n",
      "  File \"/anaconda3/lib/python3.7/wsgiref/handlers.py\", line 274, in write\n",
      "    self.send_headers()\n",
      "  File \"/anaconda3/lib/python3.7/wsgiref/handlers.py\", line 332, in send_headers\n",
      "    self.send_preamble()\n",
      "  File \"/anaconda3/lib/python3.7/wsgiref/handlers.py\", line 258, in send_preamble\n",
      "    self._write(('Server: %s\\r\\n' % self.server_software).encode('iso-8859-1'))\n",
      "  File \"/anaconda3/lib/python3.7/wsgiref/handlers.py\", line 453, in _write\n",
      "    result = self.stdout.write(data)\n",
      "  File \"/anaconda3/lib/python3.7/socketserver.py\", line 796, in write\n",
      "    self._sock.sendall(b)\n",
      "BrokenPipeError: [Errno 32] Broken pipe\n",
      "\n",
      "During handling of the above exception, another exception occurred:\n",
      "\n",
      "Traceback (most recent call last):\n",
      "  File \"/anaconda3/lib/python3.7/wsgiref/handlers.py\", line 141, in run\n",
      "    self.handle_error()\n",
      "  File \"/anaconda3/lib/python3.7/wsgiref/handlers.py\", line 368, in handle_error\n",
      "    self.finish_response()\n",
      "  File \"/anaconda3/lib/python3.7/wsgiref/handlers.py\", line 180, in finish_response\n",
      "    self.write(data)\n",
      "  File \"/anaconda3/lib/python3.7/wsgiref/handlers.py\", line 274, in write\n",
      "    self.send_headers()\n",
      "  File \"/anaconda3/lib/python3.7/wsgiref/handlers.py\", line 331, in send_headers\n",
      "    if not self.origin_server or self.client_is_modern():\n",
      "  File \"/anaconda3/lib/python3.7/wsgiref/handlers.py\", line 344, in client_is_modern\n",
      "    return self.environ['SERVER_PROTOCOL'].upper() != 'HTTP/0.9'\n",
      "TypeError: 'NoneType' object is not subscriptable\n",
      "\n",
      "During handling of the above exception, another exception occurred:\n",
      "\n",
      "Traceback (most recent call last):\n",
      "  File \"/anaconda3/lib/python3.7/socketserver.py\", line 313, in _handle_request_noblock\n",
      "    self.process_request(request, client_address)\n",
      "  File \"/anaconda3/lib/python3.7/socketserver.py\", line 344, in process_request\n",
      "    self.finish_request(request, client_address)\n",
      "  File \"/anaconda3/lib/python3.7/socketserver.py\", line 357, in finish_request\n",
      "    self.RequestHandlerClass(request, client_address, self)\n",
      "  File \"/anaconda3/lib/python3.7/socketserver.py\", line 717, in __init__\n",
      "    self.handle()\n",
      "  File \"/anaconda3/lib/python3.7/wsgiref/simple_server.py\", line 133, in handle\n",
      "    handler.run(self.server.get_app())\n",
      "  File \"/anaconda3/lib/python3.7/wsgiref/handlers.py\", line 144, in run\n",
      "    self.close()\n",
      "  File \"/anaconda3/lib/python3.7/wsgiref/simple_server.py\", line 35, in close\n",
      "    self.status.split(' ',1)[0], self.bytes_sent\n",
      "AttributeError: 'NoneType' object has no attribute 'split'\n",
      "----------------------------------------\n",
      "127.0.0.1 - - [26/Nov/2018 18:32:06] \"GET /1 HTTP/1.1\" 404 722\n"
     ]
    },
    {
     "name": "stderr",
     "output_type": "stream",
     "text": [
      "127.0.0.1 - - [26/Nov/2018 18:33:05] \"GET /login HTTP/1.1\" 404 730\n",
      "Traceback (most recent call last):\n",
      "  File \"/anaconda3/lib/python3.7/site-packages/bottle.py\", line 862, in _handle\n",
      "    return route.call(**args)\n",
      "  File \"/anaconda3/lib/python3.7/site-packages/bottle.py\", line 1740, in wrapper\n",
      "    rv = callback(*a, **ka)\n",
      "  File \"<ipython-input-2-7fa93a6709a8>\", line 16, in get_document\n",
      "    entity = db['documents'].find_one({'_id':id})\n",
      "  File \"/anaconda3/lib/python3.7/site-packages/pymongo/collection.py\", line 1262, in find_one\n",
      "    for result in cursor.limit(-1):\n",
      "  File \"/anaconda3/lib/python3.7/site-packages/pymongo/cursor.py\", line 1189, in next\n",
      "    if len(self.__data) or self._refresh():\n",
      "  File \"/anaconda3/lib/python3.7/site-packages/pymongo/cursor.py\", line 1087, in _refresh\n",
      "    self.__session = self.__collection.database.client._ensure_session()\n",
      "  File \"/anaconda3/lib/python3.7/site-packages/pymongo/mongo_client.py\", line 1563, in _ensure_session\n",
      "    return self.__start_session(True, causal_consistency=False)\n",
      "  File \"/anaconda3/lib/python3.7/site-packages/pymongo/mongo_client.py\", line 1516, in __start_session\n",
      "    server_session = self._get_server_session()\n",
      "  File \"/anaconda3/lib/python3.7/site-packages/pymongo/mongo_client.py\", line 1549, in _get_server_session\n",
      "    return self._topology.get_server_session()\n",
      "  File \"/anaconda3/lib/python3.7/site-packages/pymongo/topology.py\", line 427, in get_server_session\n",
      "    None)\n",
      "  File \"/anaconda3/lib/python3.7/site-packages/pymongo/topology.py\", line 199, in _select_servers_loop\n",
      "    self._error_message(selector))\n",
      "pymongo.errors.ServerSelectionTimeoutError: localhost:27017: [Errno 61] Connection refused\n",
      "127.0.0.1 - - [26/Nov/2018 18:33:43] \"GET /documents/1 HTTP/1.1\" 500 752\n",
      "Traceback (most recent call last):\n",
      "  File \"/anaconda3/lib/python3.7/wsgiref/handlers.py\", line 138, in run\n",
      "    self.finish_response()\n",
      "  File \"/anaconda3/lib/python3.7/wsgiref/handlers.py\", line 180, in finish_response\n",
      "    self.write(data)\n",
      "  File \"/anaconda3/lib/python3.7/wsgiref/handlers.py\", line 274, in write\n",
      "    self.send_headers()\n",
      "  File \"/anaconda3/lib/python3.7/wsgiref/handlers.py\", line 332, in send_headers\n",
      "    self.send_preamble()\n",
      "  File \"/anaconda3/lib/python3.7/wsgiref/handlers.py\", line 255, in send_preamble\n",
      "    ('Date: %s\\r\\n' % format_date_time(time.time())).encode('iso-8859-1')\n",
      "  File \"/anaconda3/lib/python3.7/wsgiref/handlers.py\", line 453, in _write\n",
      "    result = self.stdout.write(data)\n",
      "  File \"/anaconda3/lib/python3.7/socketserver.py\", line 796, in write\n",
      "    self._sock.sendall(b)\n",
      "BrokenPipeError: [Errno 32] Broken pipe\n",
      "127.0.0.1 - - [26/Nov/2018 18:33:43] \"GET /documents/1 HTTP/1.1\" 500 59\n",
      "----------------------------------------\n",
      "Exception happened during processing of request from ('127.0.0.1', 58459)\n",
      "Traceback (most recent call last):\n",
      "  File \"/anaconda3/lib/python3.7/wsgiref/handlers.py\", line 138, in run\n",
      "    self.finish_response()\n",
      "  File \"/anaconda3/lib/python3.7/wsgiref/handlers.py\", line 180, in finish_response\n",
      "    self.write(data)\n",
      "  File \"/anaconda3/lib/python3.7/wsgiref/handlers.py\", line 274, in write\n",
      "    self.send_headers()\n",
      "  File \"/anaconda3/lib/python3.7/wsgiref/handlers.py\", line 332, in send_headers\n",
      "    self.send_preamble()\n",
      "  File \"/anaconda3/lib/python3.7/wsgiref/handlers.py\", line 255, in send_preamble\n",
      "    ('Date: %s\\r\\n' % format_date_time(time.time())).encode('iso-8859-1')\n",
      "  File \"/anaconda3/lib/python3.7/wsgiref/handlers.py\", line 453, in _write\n",
      "    result = self.stdout.write(data)\n",
      "  File \"/anaconda3/lib/python3.7/socketserver.py\", line 796, in write\n",
      "    self._sock.sendall(b)\n",
      "BrokenPipeError: [Errno 32] Broken pipe\n",
      "\n",
      "During handling of the above exception, another exception occurred:\n",
      "\n",
      "Traceback (most recent call last):\n",
      "  File \"/anaconda3/lib/python3.7/wsgiref/handlers.py\", line 141, in run\n",
      "    self.handle_error()\n",
      "  File \"/anaconda3/lib/python3.7/wsgiref/handlers.py\", line 368, in handle_error\n",
      "    self.finish_response()\n",
      "  File \"/anaconda3/lib/python3.7/wsgiref/handlers.py\", line 180, in finish_response\n",
      "    self.write(data)\n",
      "  File \"/anaconda3/lib/python3.7/wsgiref/handlers.py\", line 274, in write\n",
      "    self.send_headers()\n",
      "  File \"/anaconda3/lib/python3.7/wsgiref/handlers.py\", line 331, in send_headers\n",
      "    if not self.origin_server or self.client_is_modern():\n",
      "  File \"/anaconda3/lib/python3.7/wsgiref/handlers.py\", line 344, in client_is_modern\n",
      "    return self.environ['SERVER_PROTOCOL'].upper() != 'HTTP/0.9'\n",
      "TypeError: 'NoneType' object is not subscriptable\n",
      "\n",
      "During handling of the above exception, another exception occurred:\n",
      "\n",
      "Traceback (most recent call last):\n",
      "  File \"/anaconda3/lib/python3.7/socketserver.py\", line 313, in _handle_request_noblock\n",
      "    self.process_request(request, client_address)\n",
      "  File \"/anaconda3/lib/python3.7/socketserver.py\", line 344, in process_request\n",
      "    self.finish_request(request, client_address)\n",
      "  File \"/anaconda3/lib/python3.7/socketserver.py\", line 357, in finish_request\n",
      "    self.RequestHandlerClass(request, client_address, self)\n",
      "  File \"/anaconda3/lib/python3.7/socketserver.py\", line 717, in __init__\n",
      "    self.handle()\n",
      "  File \"/anaconda3/lib/python3.7/wsgiref/simple_server.py\", line 133, in handle\n",
      "    handler.run(self.server.get_app())\n",
      "  File \"/anaconda3/lib/python3.7/wsgiref/handlers.py\", line 144, in run\n",
      "    self.close()\n",
      "  File \"/anaconda3/lib/python3.7/wsgiref/simple_server.py\", line 35, in close\n",
      "    self.status.split(' ',1)[0], self.bytes_sent\n",
      "AttributeError: 'NoneType' object has no attribute 'split'\n",
      "----------------------------------------\n",
      "127.0.0.1 - - [26/Nov/2018 18:33:43] \"GET /documents HTTP/1.1\" 405 742\n",
      "Traceback (most recent call last):\n",
      "  File \"/anaconda3/lib/python3.7/wsgiref/handlers.py\", line 138, in run\n",
      "    self.finish_response()\n",
      "  File \"/anaconda3/lib/python3.7/wsgiref/handlers.py\", line 180, in finish_response\n",
      "    self.write(data)\n",
      "  File \"/anaconda3/lib/python3.7/wsgiref/handlers.py\", line 274, in write\n",
      "    self.send_headers()\n",
      "  File \"/anaconda3/lib/python3.7/wsgiref/handlers.py\", line 332, in send_headers\n",
      "    self.send_preamble()\n",
      "  File \"/anaconda3/lib/python3.7/wsgiref/handlers.py\", line 255, in send_preamble\n",
      "    ('Date: %s\\r\\n' % format_date_time(time.time())).encode('iso-8859-1')\n",
      "  File \"/anaconda3/lib/python3.7/wsgiref/handlers.py\", line 453, in _write\n",
      "    result = self.stdout.write(data)\n",
      "  File \"/anaconda3/lib/python3.7/socketserver.py\", line 796, in write\n",
      "    self._sock.sendall(b)\n",
      "BrokenPipeError: [Errno 32] Broken pipe\n",
      "127.0.0.1 - - [26/Nov/2018 18:33:43] \"GET /documents HTTP/1.1\" 500 59\n",
      "----------------------------------------\n",
      "Exception happened during processing of request from ('127.0.0.1', 58479)\n",
      "Traceback (most recent call last):\n",
      "  File \"/anaconda3/lib/python3.7/wsgiref/handlers.py\", line 138, in run\n",
      "    self.finish_response()\n",
      "  File \"/anaconda3/lib/python3.7/wsgiref/handlers.py\", line 180, in finish_response\n",
      "    self.write(data)\n",
      "  File \"/anaconda3/lib/python3.7/wsgiref/handlers.py\", line 274, in write\n",
      "    self.send_headers()\n",
      "  File \"/anaconda3/lib/python3.7/wsgiref/handlers.py\", line 332, in send_headers\n",
      "    self.send_preamble()\n",
      "  File \"/anaconda3/lib/python3.7/wsgiref/handlers.py\", line 255, in send_preamble\n",
      "    ('Date: %s\\r\\n' % format_date_time(time.time())).encode('iso-8859-1')\n",
      "  File \"/anaconda3/lib/python3.7/wsgiref/handlers.py\", line 453, in _write\n",
      "    result = self.stdout.write(data)\n",
      "  File \"/anaconda3/lib/python3.7/socketserver.py\", line 796, in write\n",
      "    self._sock.sendall(b)\n",
      "BrokenPipeError: [Errno 32] Broken pipe\n",
      "\n",
      "During handling of the above exception, another exception occurred:\n",
      "\n",
      "Traceback (most recent call last):\n",
      "  File \"/anaconda3/lib/python3.7/wsgiref/handlers.py\", line 141, in run\n",
      "    self.handle_error()\n",
      "  File \"/anaconda3/lib/python3.7/wsgiref/handlers.py\", line 368, in handle_error\n",
      "    self.finish_response()\n",
      "  File \"/anaconda3/lib/python3.7/wsgiref/handlers.py\", line 180, in finish_response\n",
      "    self.write(data)\n",
      "  File \"/anaconda3/lib/python3.7/wsgiref/handlers.py\", line 274, in write\n",
      "    self.send_headers()\n",
      "  File \"/anaconda3/lib/python3.7/wsgiref/handlers.py\", line 331, in send_headers\n",
      "    if not self.origin_server or self.client_is_modern():\n",
      "  File \"/anaconda3/lib/python3.7/wsgiref/handlers.py\", line 344, in client_is_modern\n",
      "    return self.environ['SERVER_PROTOCOL'].upper() != 'HTTP/0.9'\n",
      "TypeError: 'NoneType' object is not subscriptable\n",
      "\n",
      "During handling of the above exception, another exception occurred:\n",
      "\n",
      "Traceback (most recent call last):\n",
      "  File \"/anaconda3/lib/python3.7/socketserver.py\", line 313, in _handle_request_noblock\n",
      "    self.process_request(request, client_address)\n",
      "  File \"/anaconda3/lib/python3.7/socketserver.py\", line 344, in process_request\n",
      "    self.finish_request(request, client_address)\n",
      "  File \"/anaconda3/lib/python3.7/socketserver.py\", line 357, in finish_request\n",
      "    self.RequestHandlerClass(request, client_address, self)\n",
      "  File \"/anaconda3/lib/python3.7/socketserver.py\", line 717, in __init__\n",
      "    self.handle()\n",
      "  File \"/anaconda3/lib/python3.7/wsgiref/simple_server.py\", line 133, in handle\n",
      "    handler.run(self.server.get_app())\n",
      "  File \"/anaconda3/lib/python3.7/wsgiref/handlers.py\", line 144, in run\n",
      "    self.close()\n",
      "  File \"/anaconda3/lib/python3.7/wsgiref/simple_server.py\", line 35, in close\n",
      "    self.status.split(' ',1)[0], self.bytes_sent\n",
      "AttributeError: 'NoneType' object has no attribute 'split'\n",
      "----------------------------------------\n"
     ]
    }
   ],
   "source": [
    "run(host='localhost', port=8080)"
   ]
  },
  {
   "cell_type": "code",
   "execution_count": null,
   "metadata": {},
   "outputs": [],
   "source": []
  }
 ],
 "metadata": {
  "kernelspec": {
   "display_name": "Python 3",
   "language": "python",
   "name": "python3"
  },
  "language_info": {
   "codemirror_mode": {
    "name": "ipython",
    "version": 3
   },
   "file_extension": ".py",
   "mimetype": "text/x-python",
   "name": "python",
   "nbconvert_exporter": "python",
   "pygments_lexer": "ipython3",
   "version": "3.7.0"
  }
 },
 "nbformat": 4,
 "nbformat_minor": 2
}
